Workbook

Sheet claim_data
A1: Claim ID | B1: Provider ID | C1: Patient ID | D1: Date of Service | E1: Procedure Code | F1: CPT Codes | G1: Diagnosis Code | H1: Billed Amount | I1: Allowed Amount | J1: Paid Amount | K1: Balance | L1: Denied Amount | M1: Denial Rate | N1: Insurance Type | O1: Claim Status | P1: Denial Reason | Q1: Follow-up Required | R1: AR Status | S1: Outcome | T1: Facility | U1: Payment Date | V1: Days in AR | W1: Aging Bucket
A2: 0HO1FSN4AP | B2: 126528997 | C2: 7936697103 | D2: 45545 | E2: 99231 | F2: 93000 | G2: A02.1 | H2: 39574 | I2: 33638 | J2: 32965.24 | K2: 0 | L2: 672.76 | M2: 0.02 | N2: Self-Pay | O2: Paid | P2: Incorrect billing information | Q2: Yes | R2: Pending | S2: Partially Paid | T2: Baltimore Infusion Center | U2: 45683 | V2: =U2-D2 -> 138 | W2: =IF(V2="","",IF(V2<30,"0-29",IF(V2<60,"30-59",IF(V2<90,"60-89",IF(V2<120,"90-119",IF(V2<150,"120-149",IF(V2<180,"150-179",IF(V2<210,"180-209",IF(V2<240,"210-239",IF(V2<270,"240-269",IF(V2<300,"270-299",IF(V2<330,"300-329",IF(V2<360,"330-359","360+"))))))))))))) -> 120-149
A3: 9U86CI2P5A | B3: 6986719948 | C3: 1547160031 | D3: 45918 | E3: 99213 | F3: 80053 | G3: A16.5 | H3: 44842 | I3: 32286 | J3: 29703.12 | K3: 0 | L3: 2582.88 | M3: 0.08 | N3: Medicare | O3: Paid | P3: Pre-existing condition | Q3: Yes | R3: Open | S3: Denied | T3: Columbia Infusion Center | U3: 46077 | V3: =U3-D3 -> 159 | W3: =IF(V3="","",IF(V3<30,"0-29",IF(V3<60,"30-59",IF(V3<90,"60-89",IF(V3<120,"90-119",IF(V3<150,"120-149",IF(V3<180,"150-179",IF(V3<210,"180-209",IF(V3<240,"210-239",IF(V3<270,"240-269",IF(V3<300,"270-299",IF(V3<330,"300-329",IF(V3<360,"330-359","360+"))))))))))))) -> 150-179
A4: 1QEU1AIDAU | B4: 1355108115 | C4: 2611585318 | D4: 45739 | E4: 99213 | F4: 99212 | G4: A00.1 | H4: 86052 | I4: 67121 | J4: 47756.8 | K4: 5940 | L4: 13424.2 | M4: 0.2 | N4: UHC | O4: Under Review | P4: Duplicate claim | Q4: No | R4: Denied | S4: Denied | T4: Columbia Infusion Center | U4: 45897 | V4: =U4-D4 -> 158 | W4: =IF(V4="","",IF(V4<30,"0-29",IF(V4<60,"30-59",IF(V4<90,"60-89",IF(V4<120,"90-119",IF(V4<150,"120-149",IF(V4<180,"150-179",IF(V4<210,"180-209",IF(V4<240,"210-239",IF(V4<270,"240-269",IF(V4<300,"270-299",IF(V4<330,"300-329",IF(V4<360,"330-359","360+"))))))))))))) -> 150-179
A5: WH7XDS8CEO | B5: 9991055906 | C5: 7167948632 | D5: 45418 | E5: 99215 | F5: 90834 | G5: A18.6 | H5: 42951 | I5: 30925 | J5: 21981 | K5: 6470 | L5: 2474 | M5: 0.08 | N5: Medicare | O5: Denied | P5: Authorization not obtained | Q5: No | R5: Partially Paid | S5: Denied | T5: Baltimore Infusion Center | U5: 45781 | V5: =U5-D5 -> 363 | W5: =IF(V5="","",IF(V5<30,"0-29",IF(V5<60,"30-59",IF(V5<90,"60-89",IF(V5<120,"90-119",IF(V5<150,"120-149",IF(V5<180,"150-179",IF(V5<210,"180-209",IF(V5<240,"210-239",IF(V5<270,"240-269",IF(V5<300,"270-299",IF(V5<330,"300-329",IF(V5<360,"330-359","360+"))))))))))))) -> 360+
A6: M6OJEZ8KGI | B6: 7382167012 | C6: 2140226267 | D6: 45828 | E6: 99238 | F6: 99205 | G6: A17.9 | H6: 94194 | I6: 67820 | J6: 46498.4 | K6: 15896 | L6: 5425.6 | M6: 0.08 | N6: Medicare | O6: Denied | P6: Authorization not obtained | Q6: No | R6: On Hold | S6: Denied | T6: Columbia Infusion Center | U6: 46024 | V6: =U6-D6 -> 196 | W6: =IF(V6="","",IF(V6<30,"0-29",IF(V6<60,"30-59",IF(V6<90,"60-89",IF(V6<120,"90-119",IF(V6<150,"120-149",IF(V6<180,"150-179",IF(V6<210,"180-209",IF(V6<240,"210-239",IF(V6<270,"240-269",IF(V6<300,"270-299",IF(V6<330,"300-329",IF(V6<360,"330-359","360+"))))))))))))) -> 180-209
A7: NST1AJ3BG4 | B7: 2460400334 | C7: 5437847378 | D7: 45618 | E7: 99231 | F7: 99214 | G7: A02.1 | H7: 29538 | I7: 25107 | J7: 24604.86 | K7: 0 | L7: 502.14 | M7: 0.02 | N7: Self-Pay | O7: Paid | P7: Patient eligibility issues | Q7: No | R7: Pending | S7: Partially Paid | T7: Columbia Infusion Center | U7: 46007 | V7: =U7-D7 -> 389 | W7: =IF(V7="","",IF(V7<30,"0-29",IF(V7<60,"30-59",IF(V7<90,"60-89",IF(V7<120,"90-119",IF(V7<150,"120-149",IF(V7<180,"150-179",IF(V7<210,"180-209",IF(V7<240,"210-239",IF(V7<270,"240-269",IF(V7<300,"270-299",IF(V7<330,"300-329",IF(V7<360,"330-359","360+"))))))))))))) -> 360+
A8: G7C9QQKWHN | B8: 4996652383 | C8: 1558663046 | D8: 45675 | E8: 99221 | F8: 99214 | G8: A01.9 | H8: 59966 | I8: 43176 | J8: 24673.92 | K8: 15048 | L8: 3454.08 | M8: 0.08 | N8: Medicare | O8: Denied | P8: Incorrect billing information | Q8: No | R8: Closed | S8: Paid | T8: Towson Infusion Center | U8: 45869 | V8: =U8-D8 -> 194 | W8: =IF(V8="","",IF(V8<30,"0-29",IF(V8<60,"30-59",IF(V8<90,"60-89",IF(V8<120,"90-119",IF(V8<150,"120-149",IF(V8<180,"150-179",IF(V8<210,"180-209",IF(V8<240,"210-239",IF(V8<270,"240-269",IF(V8<300,"270-299",IF(V8<330,"300-329",IF(V8<360,"330-359","360+"))))))))))))) -> 180-209
A9: GTGZLOTL2C | B9: 7437563222 | C9: 5362322108 | D9: 45725 | E9: 99213 | F9: 80053 | G9: A07.8 | H9: 33353 | I9: 21679 | J9: 16592.52 | K9: 2485 | L9: 2601.48 | M9: 0.12 | N9: Medicaid | O9: Under Review | P9: Patient eligibility issues | Q9: No | R9: Open | S9: Paid | T9: Columbia Infusion Center | U9: 45801 | V9: =U9-D9 -> 76 | W9: =IF(V9="","",IF(V9<30,"0-29",IF(V9<60,"30-59",IF(V9<90,"60-89",IF(V9<120,"90-119",IF(V9<150,"120-149",IF(V9<180,"150-179",IF(V9<210,"180-209",IF(V9<240,"210-239",IF(V9<270,"240-269",IF(V9<300,"270-299",IF(V9<330,"300-329",IF(V9<360,"330-359","360+"))))))))))))) -> 60-89
A10: TLU7MTJ63J | B10: 6675789567 | C10: 1861061750 | D10: 45617 | E10: 99238 | F10: 99211 | G10: A05.4 | H10: 38944 | I10: 28040 | J10: 14855.8 | K10: 10941 | L10: 2243.2 | M10: 0.08 | N10: Medicare | O10: Denied | P10: Authorization not obtained | Q10: No | R10: Closed | S10: Partially Paid | T10: Towson Infusion Center | U10: 45703 | V10: =U10-D10 -> 86 | W10: =IF(V10="","",IF(V10<30,"0-29",IF(V10<60,"30-59",IF(V10<90,"60-89",IF(V10<120,"90-119",IF(V10<150,"120-149",IF(V10<180,"150-179",IF(V10<210,"180-209",IF(V10<240,"210-239",IF(V10<270,"240-269",IF(V10<300,"270-299",IF(V10<330,"300-329",IF(V10<360,"330-359","360+"))))))))))))) -> 60-89
A11: 44K5PG8X8S | B11: 7933652528 | C11: 2435590086 | D11: 45863 | E11: 99221 | F11: 99285 | G11: A09.9 | H11: 46527 | I11: 33499 | J11: 30819.08 | K11: 0 | L11: 2679.92 | M11: 0.08 | N11: Medicare | O11: Paid | P11: Patient eligibility issues | Q11: No | R11: On Hold | S11: Partially Paid | T11: Baltimore Infusion Center | U11: 45918 | V11: =U11-D11 -> 55 | W11: =IF(V11="","",IF(V11<30,"0-29",IF(V11<60,"30-59",IF(V11<90,"60-89",IF(V11<120,"90-119",IF(V11<150,"120-149",IF(V11<180,"150-179",IF(V11<210,"180-209",IF(V11<240,"210-239",IF(V11<270,"240-269",IF(V11<300,"270-299",IF(V11<330,"300-329",IF(V11<360,"330-359","360+"))))))))))))) -> 30-59
A12: TO2JYK61C0 | B12: 2267536625 | C12: 825710946 | D12: 45950 | E12: 99221 | F12: 81000 | G12: A03.9 | H12: 91352 | I12: 65773 | J12: 52083.16 | K12: 8428 | L12: 5261.84 | M12: 0.08 | N12: Medicare | O12: Under Review | P12: Pre-existing condition | Q12: Yes | R12: Denied | S12: Partially Paid | T12: Columbia Infusion Center | U12: 46004 | V12: =U12-D12 -> 54 | W12: =IF(V12="","",IF(V12<30,"0-29",IF(V12<60,"30-59",IF(V12<90,"60-89",IF(V12<120,"90-119",IF(V12<150,"120-149",IF(V12<180,"150-179",IF(V12<210,"180-209",IF(V12<240,"210-239",IF(V12<270,"240-269",IF(V12<300,"270-299",IF(V12<330,"300-329",IF(V12<360,"330-359","360+"))))))))))))) -> 30-59
A13: DOX1BBCXK5 | B13: 5416951835 | C13: 7549905083 | D13: 45485 | E13: 99223 | F13: 99283 | G13: A02.2 | H13: 65390 | I13: 42504 | J13: 34642.52 | K13: 2761 | L13: 5100.48 | M13: 0.12 | N13: Medicaid | O13: Under Review | P13: Lack of medical necessity | Q13: No | R13: On Hold | S13: Denied | T13: Towson Infusion Center | U13: 45663 | V13: =U13-D13 -> 178 | W13: =IF(V13="","",IF(V13<30,"0-29",IF(V13<60,"30-59",IF(V13<90,"60-89",IF(V13<120,"90-119",IF(V13<150,"120-149",IF(V13<180,"150-179",IF(V13<210,"180-209",IF(V13<240,"210-239",IF(V13<270,"240-269",IF(V13<300,"270-299",IF(V13<330,"300-329",IF(V13<360,"330-359","360+"))))))))))))) -> 150-179
... A3001: 7X1X5JAH53 | B3001: 6063011370 | C3001: 7362907927 | D3001: 45782 | E3001: 99223 | F3001: 99212 | G3001: A06.8 | H3001: 26073 | I3001: 18773 | J3001: 14786.16 | K3001: 2485 | L3001: 1501.84 | M3001: 0.08 | N3001: Medicare | O3001: Under Review | P3001: Lack of medical necessity | Q3001: No | R3001: Open | S3001: Partially Paid | T3001: Baltimore Infusion Center | U3001: 46064 | V3001: =U3001-D3001 -> 282 | W3001: =IF(V3001="","",IF(V3001<30,"0-29",IF(V3001<60,"30-59",IF(V3001<90,"60-89",IF(V3001<120,"90-119",IF(V3001<150,"120-149",IF(V3001<180,"150-179",IF(V3001<210,"180-209",IF(V3001<240,"210-239",IF(V3001<270,"240-269",IF(V3001<300,"270-299",IF(V3001<330,"300-329",IF(V3001<360,"330-359","360+"))))))))))))) -> 270-299
A3002: YHC8HFB9E9 | B3002: 4930305039 | C3002: 7694919628 | D3002: 45745 | E3002: 99222 | F3002: 99285 | G3002: A15.5 | H3002: 71454 | I3002: 55734 | J3002: 37604.2 | K3002: 6983 | L3002: 11146.8 | M3002: 0.2 | N3002: UHC | O3002: Under Review | P3002: Patient eligibility issues | Q3002: No | R3002: Partially Paid | S3002: Partially Paid | T3002: Columbia Infusion Center | U3002: 45825 | V3002: 80 | W3002: =IF(V3002="","",IF(V3002<30,"0-29",IF(V3002<60,"30-59",IF(V3002<90,"60-89",IF(V3002<120,"90-119",IF(V3002<150,"120-149",IF(V3002<180,"150-179",IF(V3002<210,"180-209",IF(V3002<240,"210-239",IF(V3002<270,"240-269",IF(V3002<300,"270-299",IF(V3002<330,"300-329",IF(V3002<360,"330-359","360+"))))))))))))) -> 60-89
A3003: BLUVXOAOC6 | B3003: 640364537 | C3003: 1838497112 | D3003: 45567 | E3003: 99213 | F3003: 99202 | G3003: A13.1 | H3003: 44418 | I3003: 36423 | J3003: 29866.86 | K3003: 0 | L3003: 6556.14 | M3003: 0.18 | N3003: BCBS | O3003: Paid | P3003: Missing documentation | Q3003: Yes | R3003: Closed | S3003: Paid | T3003: Columbia Infusion Center | U3003: 45614 | V3003: 47 | W3003: =IF(V3003="","",IF(V3003<30,"0-29",IF(V3003<60,"30-59",IF(V3003<90,"60-89",IF(V3003<120,"90-119",IF(V3003<150,"120-149",IF(V3003<180,"150-179",IF(V3003<210,"180-209",IF(V3003<240,"210-239",IF(V3003<270,"240-269",IF(V3003<300,"270-299",IF(V3003<330,"300-329",IF(V3003<360,"330-359","360+"))))))))))))) -> 30-59
A3004: OZI25YQMW6 | B3004: 2596299689 | C3004: 5841713967 | D3004: 45681 | E3004: 99213 | F3004: 99212 | G3004: A16.2 | H3004: 57972 | I3004: 46378 | J3004: 22982.08 | K3004: 16903 | L3004: 6492.92 | M3004: 0.14 | N3004: Aetna | O3004: Denied | P3004: Patient eligibility issues | Q3004: No | R3004: Closed | S3004: Partially Paid | T3004: Towson Infusion Center | U3004: 45748 | V3004: 67 | W3004: =IF(V3004="","",IF(V3004<30,"0-29",IF(V3004<60,"30-59",IF(V3004<90,"60-89",IF(V3004<120,"90-119",IF(V3004<150,"120-149",IF(V3004<180,"150-179",IF(V3004<210,"180-209",IF(V3004<240,"210-239",IF(V3004<270,"240-269",IF(V3004<300,"270-299",IF(V3004<330,"300-329",IF(V3004<360,"330-359","360+"))))))))))))) -> 60-89
A3005: TE6HA6VD8D | B3005: 4513978066 | C3005: 4476704092 | D3005: 45615 | E3005: 99222 | F3005: 36415 | G3005: A05.1 | H3005: 75163 | I3005: 61634 | J3005: 50539.88 | K3005: 0 | L3005: 11094.12 | M3005: 0.18 | N3005: BCBS | O3005: Paid | P3005: Incorrect billing information | Q3005: No | R3005: Pending | S3005: Denied | T3005: Towson Infusion Center | U3005: 45662 | V3005: 47 | W3005: =IF(V3005="","",IF(V3005<30,"0-29",IF(V3005<60,"30-59",IF(V3005<90,"60-89",IF(V3005<120,"90-119",IF(V3005<150,"120-149",IF(V3005<180,"150-179",IF(V3005<210,"180-209",IF(V3005<240,"210-239",IF(V3005<270,"240-269",IF(V3005<300,"270-299",IF(V3005<330,"300-329",IF(V3005<360,"330-359","360+"))))))))))))) -> 30-59
A3006: BYJJ5RN7AT | B3006: 108095355 | C3006: 4265904430 | D3006: 45930 | E3006: 99232 | F3006: 80053 | G3006: A13.4 | H3006: 33166 | I3006: 25869 | J3006: 20695.2 | K3006: 0 | L3006: 5173.8 | M3006: 0.2 | N3006: UHC | O3006: Paid | P3006: Missing documentation | Q3006: No | R3006: Open | S3006: Paid | T3006: Columbia Infusion Center | U3006: 46072 | V3006: 142 | W3006: =IF(V3006="","",IF(V3006<30,"0-29",IF(V3006<60,"30-59",IF(V3006<90,"60-89",IF(V3006<120,"90-119",IF(V3006<150,"120-149",IF(V3006<180,"150-179",IF(V3006<210,"180-209",IF(V3006<240,"210-239",IF(V3006<270,"240-269",IF(V3006<300,"270-299",IF(V3006<330,"300-329",IF(V3006<360,"330-359","360+"))))))))))))) -> 120-149
A3007: ZKQHBDDOXF | B3007: 9011366887 | C3007: 8176726148 | D3007: 45739 | E3007: 99231 | F3007: 99204 | G3007: A03.3 | H3007: 86371 | I3007: 62187 | J3007: 47157.04 | K3007: 10055 | L3007: 4974.96 | M3007: 0.08 | N3007: Medicare | O3007: Under Review | P3007: Lack of medical necessity | Q3007: No | R3007: Open | S3007: Paid | T3007: Columbia Infusion Center | U3007: 45810 | V3007: 71 | W3007: =IF(V3007="","",IF(V3007<30,"0-29",IF(V3007<60,"30-59",IF(V3007<90,"60-89",IF(V3007<120,"90-119",IF(V3007<150,"120-149",IF(V3007<180,"150-179",IF(V3007<210,"180-209",IF(V3007<240,"210-239",IF(V3007<270,"240-269",IF(V3007<300,"270-299",IF(V3007<330,"300-329",IF(V3007<360,"330-359","360+"))))))))))))) -> 60-89
A3008: IF39V3XTB2 | B3008: 2384767464 | C3008: 9993638799 | D3008: 45497 | E3008: 99231 | F3008: 99282 | G3008: A13.3 | H3008: 23174 | I3008: 18076 | J3008: 14460.8 | K3008: 0 | L3008: 3615.2 | M3008: 0.2 | N3008: UHC | O3008: Paid | P3008: Pre-existing condition | Q3008: Yes | R3008: Partially Paid | S3008: Partially Paid | T3008: Baltimore Infusion Center | U3008: 45566 | V3008: 69 | W3008: =IF(V3008="","",IF(V3008<30,"0-29",IF(V3008<60,"30-59",IF(V3008<90,"60-89",IF(V3008<120,"90-119",IF(V3008<150,"120-149",IF(V3008<180,"150-179",IF(V3008<210,"180-209",IF(V3008<240,"210-239",IF(V3008<270,"240-269",IF(V3008<300,"270-299",IF(V3008<330,"300-329",IF(V3008<360,"330-359","360+"))))))))))))) -> 60-89
A3009: 5NSWN08KPT | B3009: 1611887710 | C3009: 6198100805 | D3009: 45382 | E3009: 99231 | F3009: 99282 | G3009: A04.8 | H3009: 24999 | I3009: 17999 | J3009: 14570.08 | K3009: 1989 | L3009: 1439.92 | M3009: 0.08 | N3009: Medicare | O3009: Under Review | P3009: Service not covered | Q3009: No | R3009: On Hold | S3009: Paid | T3009: Baltimore Infusion Center | U3009: 45457 | V3009: 75 | W3009: =IF(V3009="","",IF(V3009<30,"0-29",IF(V3009<60,"30-59",IF(V3009<90,"60-89",IF(V3009<120,"90-119",IF(V3009<150,"120-149",IF(V3009<180,"150-179",IF(V3009<210,"180-209",IF(V3009<240,"210-239",IF(V3009<270,"240-269",IF(V3009<300,"270-299",IF(V3009<330,"300-329",IF(V3009<360,"330-359","360+"))))))))))))) -> 60-89
A3010: E76A3HF5SV | B3010: 9874145157 | C3010: 1714594783 | D3010: 45790 | E3010: 99233 | F3010: 80053 | G3010: A11.2 | H3010: 50036 | I3010: 32523 | J3010: 18077.24 | K3010: 10543 | L3010: 3902.76 | M3010: 0.12 | N3010: Medicaid | O3010: Denied | P3010: Medical necessity | Q3010: Yes | R3010: Open | S3010: Denied | T3010: Towson Infusion Center | U3010: 45910 | V3010: 120 | W3010: =IF(V3010="","",IF(V3010<30,"0-29",IF(V3010<60,"30-59",IF(V3010<90,"60-89",IF(V3010<120,"90-119",IF(V3010<150,"120-149",IF(V3010<180,"150-179",IF(V3010<210,"180-209",IF(V3010<240,"210-239",IF(V3010<270,"240-269",IF(V3010<300,"270-299",IF(V3010<330,"300-329",IF(V3010<360,"330-359","360+"))))))))))))) -> 120-149
A3011: BQGJPJTWU6 | B3011: 5581101886 | C3011: 1570517276 | D3011: 45724 | E3011: 99213 | F3011: 81000 | G3011: A08.3 | H3011: 88790 | I3011: 57714 | J3011: 50788.32 | K3011: 0 | L3011: 6925.68 | M3011: 0.12 | N3011: Medicaid | O3011: Paid | P3011: Medical necessity | Q3011: Yes | R3011: Partially Paid | S3011: Paid | T3011: Towson Infusion Center | U3011: 45765 | V3011: 41 | W3011: =IF(V3011="","",IF(V3011<30,"0-29",IF(V3011<60,"30-59",IF(V3011<90,"60-89",IF(V3011<120,"90-119",IF(V3011<150,"120-149",IF(V3011<180,"150-179",IF(V3011<210,"180-209",IF(V3011<240,"210-239",IF(V3011<270,"240-269",IF(V3011<300,"270-299",IF(V3011<330,"300-329",IF(V3011<360,"330-359","360+"))))))))))))) -> 30-59
A3012: FWD136980J | B3012: 4860302624 | C3012: 4395220285 | D3012: 45342 | E3012: 99238 | F3012: 99215 | G3012: A02.9 | H3012: 69729 | I3012: 55783 | J3012: 47973.38 | K3012: 0 | L3012: 7809.62 | M3012: 0.14 | N3012: Aetna | O3012: Paid | P3012: Lack of medical necessity | Q3012: Yes | R3012: On Hold | S3012: Partially Paid | T3012: Columbia Infusion Center | U3012: 45374 | V3012: 32 | W3012: =IF(V3012="","",IF(V3012<30,"0-29",IF(V3012<60,"30-59",IF(V3012<90,"60-89",IF(V3012<120,"90-119",IF(V3012<150,"120-149",IF(V3012<180,"150-179",IF(V3012<210,"180-209",IF(V3012<240,"210-239",IF(V3012<270,"240-269",IF(V3012<300,"270-299",IF(V3012<330,"300-329",IF(V3012<360,"330-359","360+"))))))))))))) -> 30-59
A3013: IHJYTIHHBJ | B3013: 6869198989 | C3013: 5083541558 | D3013: 45673 | E3013: 99221 | F3013: 99214 | G3013: A13.1 | H3013: 87420 | I3013: 71684 | J3013: 58780.88 | K3013: 0 | L3013: 12903.12 | M3013: 0.18 | N3013: BCBS | O3013: Paid | P3013: Incorrect billing information | Q3013: Yes | R3013: Closed | S3013: Denied | T3013: Baltimore Infusion Center | U3013: 45812 | V3013: 139 | W3013: =IF(V3013="","",IF(V3013<30,"0-29",IF(V3013<60,"30-59",IF(V3013<90,"60-89",IF(V3013<120,"90-119",IF(V3013<150,"120-149",IF(V3013<180,"150-179",IF(V3013<210,"180-209",IF(V3013<240,"210-239",IF(V3013<270,"240-269",IF(V3013<300,"270-299",IF(V3013<330,"300-329",IF(V3013<360,"330-359","360+"))))))))))))) -> 120-149
... A13001: V3MDNC99LS | B13001: 7944923415 | C13001: 6371047449 | D13001: 45520 | E13001: 99214 | F13001: 99204 | G13001: A12.2 | H13001: 74759 | I13001: 61302 | J13001: 50267.64 | K13001: 0 | L13001: 11034.36 | M13001: 0.18 | N13001: BCBS | O13001: Paid | P13001: Incorrect billing information | Q13001: No | R13001: Closed | S13001: Paid | T13001: Towson Infusion Center | U13001: 45562 | V13001: 42 | W13001: =IF(V13001="","",IF(V13001<30,"0-29",IF(V13001<60,"30-59",IF(V13001<90,"60-89",IF(V13001<120,"90-119",IF(V13001<150,"120-149",IF(V13001<180,"150-179",IF(V13001<210,"180-209",IF(V13001<240,"210-239",IF(V13001<270,"240-269",IF(V13001<300,"270-299",IF(V13001<330,"300-329",IF(V13001<360,"330-359","360+"))))))))))))) -> 30-59

Sheet Sheet1
J1: Aetna
J2: Blue Cross Blue Shield
J3: UnitedHealthcare
J4: Cigna
J5: Humana

Sheet Analysis Dashboard
A1: DENIAL RATE BY PAYER | G1: MONTHLY REIMBURSEMENT TREND
A3: Payer | B3: Total Claims | C3: Denied Claims | D3: Denial Rate | G3: Month | H3: Total Billed | I3: Total Paid | J3: Reimbursement Rate
A4: Medicare | B4: =COUNTIF(claim_data!N:N,"Medicare") -> 2017 | C4: =COUNTIFS(claim_data!N:N,"Medicare",claim_data!O:O,"Denied") -> 689 | D4: =IF(B4>0,C4/B4,0) -> 0.34159643 | G4: 45292 | H4: {=SUMPRODUCT((MONTH(claim_data!D2:D13001)=1)*(YEAR(claim_data!D2:D13001)=2024)*claim_data!I2:I13001)} -> 27515459 | I4: {=SUMPRODUCT((MONTH(claim_data!D2:D13001)=1)*(YEAR(claim_data!D2:D13001)=2024)*claim_data!J2:J13001)} -> 20511402 | J4: =IF(H4>0,I4/H4,0) -> 0.74545011
A5: Medicaid | B5: =COUNTIF(claim_data!N:N,"Medicaid") -> 1954 | C5: =COUNTIFS(claim_data!N:N,"Medicaid",claim_data!O:O,"Denied") -> 634 | D5: =IF(B5>0,C5/B5,0) -> 0.32446264 | G5: 45323 | H5: {=SUMPRODUCT((MONTH(claim_data!D2:D13001)=2)*(YEAR(claim_data!D2:D13001)=2024)*claim_data!I2:I13001)} -> 27870140 | I5: {=SUMPRODUCT((MONTH(claim_data!D2:D13001)=2)*(YEAR(claim_data!D2:D13001)=2024)*claim_data!J2:J13001)} -> 20879165 | J5: =IF(H5>0,I5/H5,0) -> 0.74915895
A6: Self-Pay | B6: =COUNTIF(claim_data!N:N,"Self-Pay") -> 2026 | C6: =COUNTIFS(claim_data!N:N,"Self-Pay",claim_data!O:O,"Denied") -> 701 | D6: =IF(B6>0,C6/B6,0) -> 0.34600197 | G6: 45352 | H6: {=SUMPRODUCT((MONTH(claim_data!D2:D13001)=3)*(YEAR(claim_data!D2:D13001)=2024)*claim_data!I2:I13001)} -> 28418460 | I6: {=SUMPRODUCT((MONTH(claim_data!D2:D13001)=3)*(YEAR(claim_data!D2:D13001)=2024)*claim_data!J2:J13001)} -> 21327789 | J6: =IF(H6>0,I6/H6,0) -> 0.75049067
A7: Cigna | B7: =COUNTIF(claim_data!N:N,"Cigna") -> 1326 | C7: =COUNTIFS(claim_data!N:N,"Cigna",claim_data!O:O,"Denied") -> 452 | D7: =IF(B7>0,C7/B7,0) -> 0.34087481 | G7: 45383 | H7: {=SUMPRODUCT((MONTH(claim_data!D2:D13001)=4)*(YEAR(claim_data!D2:D13001)=2024)*claim_data!I2:I13001)} -> 27735241 | I7: {=SUMPRODUCT((MONTH(claim_data!D2:D13001)=4)*(YEAR(claim_data!D2:D13001)=2024)*claim_data!J2:J13001)} -> 20731174 | J7: =IF(H7>0,I7/H7,0) -> 0.74746687
A8: BCBS | B8: =COUNTIF(claim_data!N:N,"BCBS") -> 1447 | C8: =COUNTIFS(claim_data!N:N,"BCBS",claim_data!O:O,"Denied") -> 470 | D8: =IF(B8>0,C8/B8,0) -> 0.32480995 | G8: 45413 | H8: {=SUMPRODUCT((MONTH(claim_data!D2:D13001)=5)*(YEAR(claim_data!D2:D13001)=2024)*claim_data!I2:I13001)} -> 31096381 | I8: {=SUMPRODUCT((MONTH(claim_data!D2:D13001)=5)*(YEAR(claim_data!D2:D13001)=2024)*claim_data!J2:J13001)} -> 23564062 | J8: =IF(H8>0,I8/H8,0) -> 0.75777505
A9: Aetna | B9: =COUNTIF(claim_data!N:N,"Aetna") -> 1411 | C9: =COUNTIFS(claim_data!N:N,"Aetna",claim_data!O:O,"Denied") -> 462 | D9: =IF(B9>0,C9/B9,0) -> 0.32742736 | G9: 45444 | H9: {=SUMPRODUCT((MONTH(claim_data!D2:D13001)=6)*(YEAR(claim_data!D2:D13001)=2024)*claim_data!I2:I13001)} -> 26690529 | I9: {=SUMPRODUCT((MONTH(claim_data!D2:D13001)=6)*(YEAR(claim_data!D2:D13001)=2024)*claim_data!J2:J13001)} -> 19879258 | J9: =IF(H9>0,I9/H9,0) -> 0.7448057
A10: UHC | B10: =COUNTIF(claim_data!N:N,"UHC") -> 1450 | C10: =COUNTIFS(claim_data!N:N,"UHC",claim_data!O:O,"Denied") -> 480 | D10: =IF(B10>0,C10/B10,0) -> 0.33103448 | G10: 45474 | H10: {=SUMPRODUCT((MONTH(claim_data!D2:D13001)=7)*(YEAR(claim_data!D2:D13001)=2024)*claim_data!I2:I13001)} -> 29527844 | I10: {=SUMPRODUCT((MONTH(claim_data!D2:D13001)=7)*(YEAR(claim_data!D2:D13001)=2024)*claim_data!J2:J13001)} -> 22278197 | J10: =IF(H10>0,I10/H10,0) -> 0.75448098
A11: Humana | B11: =COUNTIF(claim_data!N:N,"Humana") -> 1369 | C11: =COUNTIFS(claim_data!N:N,"Humana",claim_data!O:O,"Denied") -> 459 | D11: =IF(B11>0,C11/B11,0) -> 0.33528123 | G11: 45505 | H11: {=SUMPRODUCT((MONTH(claim_data!D2:D13001)=8)*(YEAR(claim_data!D2:D13001)=2024)*claim_data!I2:I13001)} -> 29506517 | I11: {=SUMPRODUCT((MONTH(claim_data!D2:D13001)=8)*(YEAR(claim_data!D2:D13001)=2024)*claim_data!J2:J13001)} -> 22059611 | J11: =IF(H11>0,I11/H11,0) -> 0.74761828
A12: TOTAL | B12: =SUM(B4:B11) -> 13000 | C12: =SUM(C4:C11) -> 4347 | D12: =IF(B12>0,C12/B12,0) -> 0.33438462 | G12: 45536 | H12: {=SUMPRODUCT((MONTH(claim_data!D2:D13001)=9)*(YEAR(claim_data!D2:D13001)=2024)*claim_data!I2:I13001)} -> 29402198 | I12: {=SUMPRODUCT((MONTH(claim_data!D2:D13001)=9)*(YEAR(claim_data!D2:D13001)=2024)*claim_data!J2:J13001)} -> 22101207 | J12: =IF(H12>0,I12/H12,0) -> 0.75168554
G13: 45566 | H13: {=SUMPRODUCT((MONTH(claim_data!D2:D13001)=10)*(YEAR(claim_data!D2:D13001)=2024)*claim_data!I2:I13001)} -> 29407705 | I13: {=SUMPRODUCT((MONTH(claim_data!D2:D13001)=10)*(YEAR(claim_data!D2:D13001)=2024)*claim_data!J2:J13001)} -> 22298870 | J13: =IF(H13>0,I13/H13,0) -> 0.75826624
A14: REVENUE LEAKAGE BY CPT CODE | G14: 45597 | H14: {=SUMPRODUCT((MONTH(claim_data!D2:D13001)=11)*(YEAR(claim_data!D2:D13001)=2024)*claim_data!I2:I13001)} -> 27733206 | I14: {=SUMPRODUCT((MONTH(claim_data!D2:D13001)=11)*(YEAR(claim_data!D2:D13001)=2024)*claim_data!J2:J13001)} -> 21278716 | J14: =IF(H14>0,I14/H14,0) -> 0.76726492
G15: 45627 | H15: {=SUMPRODUCT((MONTH(claim_data!D2:D13001)=12)*(YEAR(claim_data!D2:D13001)=2024)*claim_data!I2:I13001)} -> 29377789 | I15: {=SUMPRODUCT((MONTH(claim_data!D2:D13001)=12)*(YEAR(claim_data!D2:D13001)=2024)*claim_data!J2:J13001)} -> 22231271 | J15: =IF(H15>0,I15/H15,0) -> 0.75673739
A16: CPT Code | B16: Total Allowed | C16: Total Paid | D16: Revenue Leakage | E16: Leakage % | G16: 45658 | H16: {=SUMPRODUCT((MONTH(claim_data!D2:D13001)=1)*(YEAR(claim_data!D2:D13001)=2025)*claim_data!I2:I13001)} -> 29811926 | I16: {=SUMPRODUCT((MONTH(claim_data!D2:D13001)=1)*(YEAR(claim_data!D2:D13001)=2025)*claim_data!J2:J13001)} -> 22513658 | J16: =IF(H16>0,I16/H16,0) -> 0.75518964
A17: 99201 | B17: =SUMIF(claim_data!F:F,"99201",claim_data!I:I) -> 26045672 | C17: =SUMIF(claim_data!F:F,"99201",claim_data!J:J) -> 19762710 | D17: =B17-C17 -> 6282961.8 | E17: =IF(B17>0,D17/B17,0) -> 0.24122863 | G17: 45689 | H17: {=SUMPRODUCT((MONTH(claim_data!D2:D13001)=2)*(YEAR(claim_data!D2:D13001)=2025)*claim_data!I2:I13001)} -> 25295562 | I17: {=SUMPRODUCT((MONTH(claim_data!D2:D13001)=2)*(YEAR(claim_data!D2:D13001)=2025)*claim_data!J2:J13001)} -> 18980481 | J17: =IF(H17>0,I17/H17,0) -> 0.75034824
A18: 99202 | B18: =SUMIF(claim_data!F:F,"99202",claim_data!I:I) -> 26221051 | C18: =SUMIF(claim_data!F:F,"99202",claim_data!J:J) -> 19651494 | D18: =B18-C18 -> 6569557.2 | E18: =IF(B18>0,D18/B18,0) -> 0.25054515 | G18: 45717 | H18: {=SUMPRODUCT((MONTH(claim_data!D2:D13001)=3)*(YEAR(claim_data!D2:D13001)=2025)*claim_data!I2:I13001)} -> 28812634 | I18: {=SUMPRODUCT((MONTH(claim_data!D2:D13001)=3)*(YEAR(claim_data!D2:D13001)=2025)*claim_data!J2:J13001)} -> 21677646 | J18: =IF(H18>0,I18/H18,0) -> 0.752366
A19: 99203 | B19: =SUMIF(claim_data!F:F,"99203",claim_data!I:I) -> 24984732 | C19: =SUMIF(claim_data!F:F,"99203",claim_data!J:J) -> 18932863 | D19: =B19-C19 -> 6051869.4 | E19: =IF(B19>0,D19/B19,0) -> 0.24222271 | G19: 45748 | H19: {=SUMPRODUCT((MONTH(claim_data!D2:D13001)=4)*(YEAR(claim_data!D2:D13001)=2025)*claim_data!I2:I13001)} -> 27367492 | I19: {=SUMPRODUCT((MONTH(claim_data!D2:D13001)=4)*(YEAR(claim_data!D2:D13001)=2025)*claim_data!J2:J13001)} -> 20591740 | J19: =IF(H19>0,I19/H19,0) -> 0.75241603
A20: 99204 | B20: =SUMIF(claim_data!F:F,"99204",claim_data!I:I) -> 25350419 | C20: =SUMIF(claim_data!F:F,"99204",claim_data!J:J) -> 18957213 | D20: =B20-C20 -> 6393205.9 | E20: =IF(B20>0,D20/B20,0) -> 0.2521933 | G20: 45778 | H20: {=SUMPRODUCT((MONTH(claim_data!D2:D13001)=5)*(YEAR(claim_data!D2:D13001)=2025)*claim_data!I2:I13001)} -> 27937889 | I20: {=SUMPRODUCT((MONTH(claim_data!D2:D13001)=5)*(YEAR(claim_data!D2:D13001)=2025)*claim_data!J2:J13001)} -> 21024873 | J20: =IF(H20>0,I20/H20,0) -> 0.75255767
A21: 99205 | B21: =SUMIF(claim_data!F:F,"99205",claim_data!I:I) -> 24813179 | C21: =SUMIF(claim_data!F:F,"99205",claim_data!J:J) -> 18830014 | D21: =B21-C21 -> 5983164.8 | E21: =IF(B21>0,D21/B21,0) -> 0.24112851 | G21: 45809 | H21: {=SUMPRODUCT((MONTH(claim_data!D2:D13001)=6)*(YEAR(claim_data!D2:D13001)=2025)*claim_data!I2:I13001)} -> 27130176 | I21: {=SUMPRODUCT((MONTH(claim_data!D2:D13001)=6)*(YEAR(claim_data!D2:D13001)=2025)*claim_data!J2:J13001)} -> 20300069 | J21: =IF(H21>0,I21/H21,0) -> 0.74824686
A22: 99211 | B22: =SUMIF(claim_data!F:F,"99211",claim_data!I:I) -> 25682461 | C22: =SUMIF(claim_data!F:F,"99211",claim_data!J:J) -> 19291182 | D22: =B22-C22 -> 6391278.5 | E22: =IF(B22>0,D22/B22,0) -> 0.24885771 | G22: 45839 | H22: {=SUMPRODUCT((MONTH(claim_data!D2:D13001)=7)*(YEAR(claim_data!D2:D13001)=2025)*claim_data!I2:I13001)} -> 29044721 | I22: {=SUMPRODUCT((MONTH(claim_data!D2:D13001)=7)*(YEAR(claim_data!D2:D13001)=2025)*claim_data!J2:J13001)} -> 22156878 | J22: =IF(H22>0,I22/H22,0) -> 0.76285386
A23: 99212 | B23: =SUMIF(claim_data!F:F,"99212",claim_data!I:I) -> 25597419 | C23: =SUMIF(claim_data!F:F,"99212",claim_data!J:J) -> 19197985 | D23: =B23-C23 -> 6399433.7 | E23: =IF(B23>0,D23/B23,0) -> 0.25000308 | G23: 45870 | H23: {=SUMPRODUCT((MONTH(claim_data!D2:D13001)=8)*(YEAR(claim_data!D2:D13001)=2025)*claim_data!I2:I13001)} -> 27358114 | I23: {=SUMPRODUCT((MONTH(claim_data!D2:D13001)=8)*(YEAR(claim_data!D2:D13001)=2025)*claim_data!J2:J13001)} -> 20609754 | J23: =IF(H23>0,I23/H23,0) -> 0.75333243
A24: 99213 | B24: =SUMIF(claim_data!F:F,"99213",claim_data!I:I) -> 24477026 | C24: =SUMIF(claim_data!F:F,"99213",claim_data!J:J) -> 18421952 | D24: =B24-C24 -> 6055074.5 | E24: =IF(B24>0,D24/B24,0) -> 0.24737787 | G24: 45901 | H24: {=SUMPRODUCT((MONTH(claim_data!D2:D13001)=9)*(YEAR(claim_data!D2:D13001)=2025)*claim_data!I2:I13001)} -> 28903205 | I24: {=SUMPRODUCT((MONTH(claim_data!D2:D13001)=9)*(YEAR(claim_data!D2:D13001)=2025)*claim_data!J2:J13001)} -> 22097689 | J24: =IF(H24>0,I24/H24,0) -> 0.76454115
A25: 99214 | B25: =SUMIF(claim_data!F:F,"99214",claim_data!I:I) -> 25354739 | C25: =SUMIF(claim_data!F:F,"99214",claim_data!J:J) -> 19302425 | D25: =B25-C25 -> 6052314.2 | E25: =IF(B25>0,D25/B25,0) -> 0.23870544 | G25: 45931 | H25: {=SUMPRODUCT((MONTH(claim_data!D2:D13001)=10)*(YEAR(claim_data!D2:D13001)=2025)*claim_data!I2:I13001)} -> 28432673 | I25: {=SUMPRODUCT((MONTH(claim_data!D2:D13001)=10)*(YEAR(claim_data!D2:D13001)=2025)*claim_data!J2:J13001)} -> 21527244 | J25: =IF(H25>0,I25/H25,0) -> 0.75713049
A26: 99215 | B26: =SUMIF(claim_data!F:F,"99215",claim_data!I:I) -> 25078630 | C26: =SUMIF(claim_data!F:F,"99215",claim_data!J:J) -> 18855909 | D26: =B26-C26 -> 6222721.2 | E26: =IF(B26>0,D26/B26,0) -> 0.24812844 | G26: TOTAL | H26: =SUM(H4:H25) -> 624375861 | I26: =SUM(I4:I25) -> 4.7062075e+08 | J26: =IF(H26>0,I26/H26,0) -> 0.75374591
A27: 99281 | B27: =SUMIF(claim_data!F:F,"99281",claim_data!I:I) -> 25045028 | C27: =SUMIF(claim_data!F:F,"99281",claim_data!J:J) -> 18865646 | D27: =B27-C27 -> 6179381.7 | E27: =IF(B27>0,D27/B27,0) -> 0.24673088
A28: 99282 | B28: =SUMIF(claim_data!F:F,"99282",claim_data!I:I) -> 23481744 | C28: =SUMIF(claim_data!F:F,"99282",claim_data!J:J) -> 17872165 | D28: =B28-C28 -> 5609579.5 | E28: =IF(B28>0,D28/B28,0) -> 0.23889109 | G28: APPEAL SUCCESS RATE ANALYSIS
A29: 99283 | B29: =SUMIF(claim_data!F:F,"99283",claim_data!I:I) -> 24030172 | C29: =SUMIF(claim_data!F:F,"99283",claim_data!J:J) -> 18052226 | D29: =B29-C29 -> 5977946.1 | E29: =IF(B29>0,D29/B29,0) -> 0.24876834
A30: 99284 | B30: =SUMIF(claim_data!F:F,"99284",claim_data!I:I) -> 25611937 | C30: =SUMIF(claim_data!F:F,"99284",claim_data!J:J) -> 19292350 | D30: =B30-C30 -> 6319586.6 | E30: =IF(B30>0,D30/B30,0) -> 0.2467438 | G30: Metric | H30: Count | I30: Percentage
A31: 99285 | B31: =SUMIF(claim_data!F:F,"99285",claim_data!I:I) -> 23712473 | C31: =SUMIF(claim_data!F:F,"99285",claim_data!J:J) -> 18050055 | D31: =B31-C31 -> 5662417.8 | E31: =IF(B31>0,D31/B31,0) -> 0.23879491 | G31: Total Denied Claims | H31: =COUNTIF(claim_data!O:O,"Denied") -> 4347
A32: 99291 | B32: =SUMIF(claim_data!F:F,"99291",claim_data!I:I) -> 25547542 | C32: =SUMIF(claim_data!F:F,"99291",claim_data!J:J) -> 19260887 | D32: =B32-C32 -> 6286654.7 | E32: =IF(B32>0,D32/B32,0) -> 0.24607669 | G32: Denied Claims - Now Paid | H32: =COUNTIFS(claim_data!O:O,"Denied",claim_data!S:S,"Paid") -> 1406 | I32: =IF(H31>0,H32/H31,0) -> 0.32344145
A33: 99292 | B33: =SUMIF(claim_data!F:F,"99292",claim_data!I:I) -> 24907553 | C33: =SUMIF(claim_data!F:F,"99292",claim_data!J:J) -> 18607676 | D33: =B33-C33 -> 6299877.4 | E33: =IF(B33>0,D33/B33,0) -> 0.2529304 | G33: Denied Claims - Partially Paid | H33: =COUNTIFS(claim_data!O:O,"Denied",claim_data!S:S,"Partially Paid") -> 1444 | I33: =IF(H31>0,H33/H31,0) -> 0.33218311
A34: 36415 | B34: =SUMIF(claim_data!F:F,"36415",claim_data!I:I) -> 22915638 | C34: =SUMIF(claim_data!F:F,"36415",claim_data!J:J) -> 17236723 | D34: =B34-C34 -> 5678915.5 | E34: =IF(B34>0,D34/B34,0) -> 0.24781834 | G34: Denied Claims - Still Denied | H34: =COUNTIFS(claim_data!O:O,"Denied",claim_data!S:S,"Denied") -> 1497 | I34: =IF(H31>0,H34/H31,0) -> 0.34437543
A35: 81000 | B35: =SUMIF(claim_data!F:F,"81000",claim_data!I:I) -> 24767202 | C35: =SUMIF(claim_data!F:F,"81000",claim_data!J:J) -> 18564057 | D35: =B35-C35 -> 6203145.1 | E35: =IF(B35>0,D35/B35,0) -> 0.25045805
A36: 85025 | B36: =SUMIF(claim_data!F:F,"85025",claim_data!I:I) -> 25429860 | C36: =SUMIF(claim_data!F:F,"85025",claim_data!J:J) -> 19020460 | D36: =B36-C36 -> 6409400.4 | E36: =IF(B36>0,D36/B36,0) -> 0.2520423 | G36: APPEAL SUCCESS RATE | H36: =H32+H33 -> 2850 | I36: =IF(H31>0,H36/H31,0) -> 0.65562457
A37: 80053 | B37: =SUMIF(claim_data!F:F,"80053",claim_data!I:I) -> 24310679 | C37: =SUMIF(claim_data!F:F,"80053",claim_data!J:J) -> 18628178 | D37: =B37-C37 -> 5682500.6 | E37: =IF(B37>0,D37/B37,0) -> 0.23374504
A38: 71046 | B38: =SUMIF(claim_data!F:F,"71046",claim_data!I:I) -> 23448900 | C38: =SUMIF(claim_data!F:F,"71046",claim_data!J:J) -> 17536397 | D38: =B38-C38 -> 5912503.4 | E38: =IF(B38>0,D38/B38,0) -> 0.25214417 | G38: Revenue Recovered via Appeals | H38: =SUMIFS(claim_data!J:J,claim_data!O:O,"Denied",claim_data!S:S,"Paid")+SUMIFS(claim_data!J:J,claim_data!O:O,"Denied",claim_data!S:S,"Partially Paid") -> 83227854
A39: 93000 | B39: =SUMIF(claim_data!F:F,"93000",claim_data!I:I) -> 26698132 | C39: =SUMIF(claim_data!F:F,"93000",claim_data!J:J) -> 20011985 | D39: =B39-C39 -> 6686147.3 | E39: =IF(B39>0,D39/B39,0) -> 0.25043502
A40: 90834 | B40: =SUMIF(claim_data!F:F,"90834",claim_data!I:I) -> 25900741 | C40: =SUMIF(claim_data!F:F,"90834",claim_data!J:J) -> 19394288 | D40: =B40-C40 -> 6506453.3 | E40: =IF(B40>0,D40/B40,0) -> 0.25120723
A41: 97110 | B41: =SUMIF(claim_data!F:F,"97110",claim_data!I:I) -> 25084167 | C41: =SUMIF(claim_data!F:F,"97110",claim_data!J:J) -> 19121977 | D41: =B41-C41 -> 5962190 | E41: =IF(B41>0,D41/B41,0) -> 0.23768738
...

Sheet Financial Analysis
A1: REIMBURSEMENT VARIANCE ANALYSIS
A3: Payer | B3: Total Billed (H) | C3: Total Allowed (I) | D3: Total Paid (J) | E3: Billed-to-Allowed Variance | F3: Allowed-to-Paid Variance | G3: Overall Reimbursement Rate
A4: Medicare | B4: =SUMIF(claim_data!N:N,"Medicare",claim_data!H:H) -> 124234963 | C4: =SUMIF(claim_data!N:N,"Medicare",claim_data!I:I) -> 89449205 | D4: =SUMIF(claim_data!N:N,"Medicare",claim_data!J:J) -> 70297221 | E4: =B4-C4 -> 34785758 | F4: =C4-D4 -> 19151984 | G4: =IF(B4=0,0,D4/B4) -> 0.56584088
A5: Medicaid | B5: =SUMIF(claim_data!N:N,"Medicaid",claim_data!H:H) -> 121811026 | C5: =SUMIF(claim_data!N:N,"Medicaid",claim_data!I:I) -> 79177233 | D5: =SUMIF(claim_data!N:N,"Medicaid",claim_data!J:J) -> 60138154 | E5: =B5-C5 -> 42633793 | F5: =C5-D5 -> 19039079 | G5: =IF(B5=0,0,D5/B5) -> 0.49370041
A6: Self-Pay | B6: =SUMIF(claim_data!N:N,"Self-Pay",claim_data!H:H) -> 128054440 | C6: =SUMIF(claim_data!N:N,"Self-Pay",claim_data!I:I) -> 108846326 | D6: =SUMIF(claim_data!N:N,"Self-Pay",claim_data!J:J) -> 91793451 | E6: =B6-C6 -> 19208114 | F6: =C6-D6 -> 17052875 | G6: =IF(B6=0,0,D6/B6) -> 0.71683146
A7: Cigna | B7: =SUMIF(claim_data!N:N,"Cigna",claim_data!H:H) -> 82911556 | C7: =SUMIF(claim_data!N:N,"Cigna",claim_data!I:I) -> 65500132 | D7: =SUMIF(claim_data!N:N,"Cigna",claim_data!J:J) -> 47400941 | E7: =B7-C7 -> 17411424 | F7: =C7-D7 -> 18099191 | G7: =IF(B7=0,0,D7/B7) -> 0.57170488
A8: BCBS | B8: =SUMIF(claim_data!N:N,"BCBS",claim_data!H:H) -> 91328700 | C8: =SUMIF(claim_data!N:N,"BCBS",claim_data!I:I) -> 74889557 | D8: =SUMIF(claim_data!N:N,"BCBS",claim_data!J:J) -> 52864406 | E8: =B8-C8 -> 16439143 | F8: =C8-D8 -> 22025151 | G8: =IF(B8=0,0,D8/B8) -> 0.57883673
A9: Aetna | B9: =SUMIF(claim_data!N:N,"Aetna",claim_data!H:H) -> 87223375 | C9: =SUMIF(claim_data!N:N,"Aetna",claim_data!I:I) -> 69778705 | D9: =SUMIF(claim_data!N:N,"Aetna",claim_data!J:J) -> 51281107 | E9: =B9-C9 -> 17444670 | F9: =C9-D9 -> 18497598 | G9: =IF(B9=0,0,D9/B9) -> 0.58792849
A10: UHC | B10: =SUMIF(claim_data!N:N,"UHC",claim_data!H:H) -> 92443712 | C10: =SUMIF(claim_data!N:N,"UHC",claim_data!I:I) -> 72106118 | D10: =SUMIF(claim_data!N:N,"UHC",claim_data!J:J) -> 49672087 | E10: =B10-C10 -> 20337594 | F10: =C10-D10 -> 22434031 | G10: =IF(B10=0,0,D10/B10) -> 0.53732251
A11: Humana | B11: =SUMIF(claim_data!N:N,"Humana",claim_data!H:H) -> 86332863 | C11: =SUMIF(claim_data!N:N,"Humana",claim_data!I:I) -> 64749820 | D11: =SUMIF(claim_data!N:N,"Humana",claim_data!J:J) -> 47271448 | E11: =B11-C11 -> 21583043 | F11: =C11-D11 -> 17478372 | G11: =IF(B11=0,0,D11/B11) -> 0.54754871
A12: TOTAL | B12: =SUM(B4:B11) -> 814340635 | C12: =SUM(C4:C11) -> 624497096 | D12: =SUM(D4:D11) -> 4.7071882e+08 | E12: =SUM(E4:E11) -> 189843539 | F12: =SUM(F4:F11) -> 1.5377828e+08 | G12: =IF(B12=0,0,D12/B12) -> 0.57803675
A14: PAYER PROFITABILITY ANALYSIS
A16: Payer | B16: Claim Count | C16: Avg Billed | D16: Avg Allowed | E16: Avg Paid | F16: Avg Denied Amt | G16: Collection Rate | H16: Profitability Score
A17: Medicare | B17: =COUNTIF(claim_data!N:N,"Medicare") -> 2017 | C17: =AVERAGEIF(claim_data!N:N,"Medicare",claim_data!H:H) -> 61593.933 | D17: =AVERAGEIF(claim_data!N:N,"Medicare",claim_data!I:I) -> 44347.647 | E17: =AVERAGEIF(claim_data!N:N,"Medicare",claim_data!J:J) -> 34852.365 | F17: =AVERAGEIF(claim_data!N:N,"Medicare",claim_data!L:L) -> 3547.8118 | G17: =IF(C17=0,0,E17/C17) -> 0.56584088 | H17: =IF(D17=0,0,(E17-F17)/D17) -> 0.70588983
A18: Medicaid | B18: =COUNTIF(claim_data!N:N,"Medicaid") -> 1954 | C18: =AVERAGEIF(claim_data!N:N,"Medicaid",claim_data!H:H) -> 62339.317 | D18: =AVERAGEIF(claim_data!N:N,"Medicaid",claim_data!I:I) -> 40520.59 | E18: =AVERAGEIF(claim_data!N:N,"Medicaid",claim_data!J:J) -> 30776.947 | F18: =AVERAGEIF(claim_data!N:N,"Medicaid",claim_data!L:L) -> 4862.4708 | G18: =IF(C18=0,0,E18/C18) -> 0.49370041 | H18: =IF(D18=0,0,(E18-F18)/D18) -> 0.63953847
A19: Self-Pay | B19: =COUNTIF(claim_data!N:N,"Self-Pay") -> 2026 | C19: =AVERAGEIF(claim_data!N:N,"Self-Pay",claim_data!H:H) -> 63205.548 | D19: =AVERAGEIF(claim_data!N:N,"Self-Pay",claim_data!I:I) -> 53724.741 | E19: =AVERAGEIF(claim_data!N:N,"Self-Pay",claim_data!J:J) -> 45307.725 | F19: =AVERAGEIF(claim_data!N:N,"Self-Pay",claim_data!L:L) -> 1074.4948 | G19: =IF(C19=0,0,E19/C19) -> 0.71683146 | H19: =IF(D19=0,0,(E19-F19)/D19) -> 0.82333073
A20: Cigna | B20: =COUNTIF(claim_data!N:N,"Cigna") -> 1326 | C20: =AVERAGEIF(claim_data!N:N,"Cigna",claim_data!H:H) -> 62527.569 | D20: =AVERAGEIF(claim_data!N:N,"Cigna",claim_data!I:I) -> 49396.781 | E20: =AVERAGEIF(claim_data!N:N,"Cigna",claim_data!J:J) -> 35747.316 | F20: =AVERAGEIF(claim_data!N:N,"Cigna",claim_data!L:L) -> 7903.485 | G20: =IF(C20=0,0,E20/C20) -> 0.57170488 | H20: =IF(D20=0,0,(E20-F20)/D20) -> 0.56367703
A21: BCBS | B21: =COUNTIF(claim_data!N:N,"BCBS") -> 1447 | C21: =AVERAGEIF(claim_data!N:N,"BCBS",claim_data!H:H) -> 63115.895 | D21: =AVERAGEIF(claim_data!N:N,"BCBS",claim_data!I:I) -> 51755.05 | E21: =AVERAGEIF(claim_data!N:N,"BCBS",claim_data!J:J) -> 36533.798 | F21: =AVERAGEIF(claim_data!N:N,"BCBS",claim_data!L:L) -> 9315.909 | G21: =IF(C21=0,0,E21/C21) -> 0.57883673 | H21: =IF(D21=0,0,(E21-F21)/D21) -> 0.52589823
A22: Aetna | B22: =COUNTIF(claim_data!N:N,"Aetna") -> 1411 | C22: =AVERAGEIF(claim_data!N:N,"Aetna",claim_data!H:H) -> 61816.708 | D22: =AVERAGEIF(claim_data!N:N,"Aetna",claim_data!I:I) -> 49453.37 | E22: =AVERAGEIF(claim_data!N:N,"Aetna",claim_data!J:J) -> 36343.804 | F22: =AVERAGEIF(claim_data!N:N,"Aetna",claim_data!L:L) -> 6923.4718 | G22: =IF(C22=0,0,E22/C22) -> 0.58792849 | H22: =IF(D22=0,0,(E22-F22)/D22) -> 0.59491056
A23: UHC | B23: =COUNTIF(claim_data!N:N,"UHC") -> 1450 | C23: =AVERAGEIF(claim_data!N:N,"UHC",claim_data!H:H) -> 63754.284 | D23: =AVERAGEIF(claim_data!N:N,"UHC",claim_data!I:I) -> 49728.357 | E23: =AVERAGEIF(claim_data!N:N,"UHC",claim_data!J:J) -> 34256.612 | F23: =AVERAGEIF(claim_data!N:N,"UHC",claim_data!L:L) -> 9945.6714 | G23: =IF(C23=0,0,E23/C23) -> 0.53732251 | H23: =IF(D23=0,0,(E23-F23)/D23) -> 0.4888748
A24: Humana | B24: =COUNTIF(claim_data!N:N,"Humana") -> 1369 | C24: =AVERAGEIF(claim_data!N:N,"Humana",claim_data!H:H) -> 63062.72 | D24: =AVERAGEIF(claim_data!N:N,"Humana",claim_data!I:I) -> 47297.166 | E24: =AVERAGEIF(claim_data!N:N,"Humana",claim_data!J:J) -> 34529.911 | F24: =AVERAGEIF(claim_data!N:N,"Humana",claim_data!L:L) -> 7094.5749 | G24: =IF(C24=0,0,E24/C24) -> 0.54754871 | H24: =IF(D24=0,0,(E24-F24)/D24) -> 0.580063
A25: TOTAL/AVG | B25: =SUM(B17:B24) -> 13000 | C25: =AVERAGE(C17:C24) -> 62676.997 | D25: =AVERAGE(D17:D24) -> 48277.963 | E25: =AVERAGE(E17:E24) -> 36043.56 | F25: =AVERAGE(F17:F24) -> 6333.4862 | G25: =AVERAGE(G17:G24) -> 0.57496426 | H25: =AVERAGE(H17:H24) -> 0.61527283
A27: FINANCIAL IMPACT ANALYSIS
A29: Metric | B29: Value | C29: % of Total Billed | D29: Impact Level
A30: Total Billed Amount | B30: =SUM(claim_data!H2:H13001) -> 814340635 | D30: Baseline
A31: Total Allowed Amount | B31: =SUM(claim_data!I2:I13001) -> 624497096 | C31: =B31/B30 -> 0.76687454 | D31: Contractual
A32: Total Paid Amount | B32: =SUM(claim_data!J2:J13001) -> 4.7071882e+08 | C32: =B32/B30 -> 0.57803675 | D32: Revenue
A33: Total Denied Amount | B33: =SUM(claim_data!L2:L13001) -> 76696988 | C33: =B33/B31 -> 0.122814 | D33: High Risk
A34: Revenue Leakage (Billed-Paid) | B34: =B30-B32 -> 3.4362182e+08 | C34: =B34/B30 -> 0.42196325 | D34: Critical
A35: Contractual Adjustment | B35: =B30-B31 -> 189843539 | C35: =B35/B30 -> 0.23312546 | D35: Expected
A37: BY FACILITY
A38: Facility | B38: Total Billed | C38: Total Paid | D38: Collection Rate
A39: Baltimore Infusion Center | B39: =SUMIF(claim_data!T:T,"Baltimore Infusion Center",claim_data!H:H) -> 273772007 | C39: =SUMIF(claim_data!T:T,"Baltimore Infusion Center",claim_data!J:J) -> 1.5778599e+08 | D39: =IF(B39=0,0,C39/B39) -> 0.57634085
A40: Columbia Infusion Center | B40: =SUMIF(claim_data!T:T,"Columbia Infusion Center",claim_data!H:H) -> 270397926 | C40: =SUMIF(claim_data!T:T,"Columbia Infusion Center",claim_data!J:J) -> 1.5678634e+08 | D40: =IF(B40=0,0,C40/B40) -> 0.57983557
A41: Towson Infusion Center | B41: =SUMIF(claim_data!T:T,"Towson Infusion Center",claim_data!H:H) -> 270170702 | C41: =SUMIF(claim_data!T:T,"Towson Infusion Center",claim_data!J:J) -> 1.5614649e+08 | D41: =IF(B41=0,0,C41/B41) -> 0.57795493
A42: TOTAL | B42: =SUM(B39:B41) -> 814340635 | C42: =SUM(C39:C41) -> 4.7071882e+08 | D42: =IF(B42=0,0,C42/B42) -> 0.57803675
A45: MONTHLY REVENUE TRENDS
A47: Month | B47: Claims | C47: Total Billed | D47: Total Paid | E47: Reimbursement Rate | F47: MoM Change
A48: 46046 | B48: {=SUMPRODUCT((MONTH(claim_data!D2:D13001)=1)*(YEAR(claim_data!D2:D13001)=2024)*1)} -> 568 | C48: {=SUMPRODUCT((MONTH(claim_data!D2:D13001)=1)*(YEAR(claim_data!D2:D13001)=2024)*(claim_data!H2:H13001))} -> 35921785 | D48: {=SUMPRODUCT((MONTH(claim_data!D2:D13001)=1)*(YEAR(claim_data!D2:D13001)=2024)*(claim_data!J2:J13001))} -> 20511402 | E48: =IF(C48=0,0,D48/C48) -> 0.57100175
A49: 46077 | B49: {=SUMPRODUCT((MONTH(claim_data!D2:D13001)=2)*(YEAR(claim_data!D2:D13001)=2024)*1)} -> 585 | C49: {=SUMPRODUCT((MONTH(claim_data!D2:D13001)=2)*(YEAR(claim_data!D2:D13001)=2024)*(claim_data!H2:H13001))} -> 36365088 | D49: {=SUMPRODUCT((MONTH(claim_data!D2:D13001)=2)*(YEAR(claim_data!D2:D13001)=2024)*(claim_data!J2:J13001))} -> 20879165 | E49: =IF(C49=0,0,D49/C49) -> 0.57415411 | F49: =IF(D48=0,0,(D49-D48)/D48) -> 0.017929668
...
